{"uid":"53e62bd92de0cd9a","name":"test_tls_enabled","fullName":"tests.integration.test_tls#test_tls_enabled","historyId":"0ebe5aa0b66f6c5314fa764ad3239c77","time":{"start":1712971395965,"stop":1712972652068,"duration":1256103},"description":"Test that TLS is enabled when relating to the TLS Certificates Operator.","descriptionHtml":"<p>Test that TLS is enabled when relating to the TLS Certificates Operator.</p>\n","status":"broken","statusMessage":"tenacity.RetryError: RetryError[<Future at 0x76fc96e4fe80 state=finished returned bool>]","statusTrace":"Traceback (most recent call last):\n  File \"/home/ubuntu/github-runner/_work/test-runners-self-hosted-postgresql-operator/test-runners-self-hosted-postgresql-operator/.tox/integration/lib/python3.10/site-packages/_pytest/runner.py\", line 340, in from_call\n    result: Optional[TResult] = func()\n  File \"/home/ubuntu/github-runner/_work/test-runners-self-hosted-postgresql-operator/test-runners-self-hosted-postgresql-operator/.tox/integration/lib/python3.10/site-packages/_pytest/runner.py\", line 240, in <lambda>\n    lambda: runtest_hook(item=item, **kwds), when=when, reraise=reraise\n  File \"/home/ubuntu/github-runner/_work/test-runners-self-hosted-postgresql-operator/test-runners-self-hosted-postgresql-operator/.tox/integration/lib/python3.10/site-packages/pluggy/_hooks.py\", line 501, in __call__\n    return self._hookexec(self.name, self._hookimpls.copy(), kwargs, firstresult)\n  File \"/home/ubuntu/github-runner/_work/test-runners-self-hosted-postgresql-operator/test-runners-self-hosted-postgresql-operator/.tox/integration/lib/python3.10/site-packages/pluggy/_manager.py\", line 119, in _hookexec\n    return self._inner_hookexec(hook_name, methods, kwargs, firstresult)\n  File \"/home/ubuntu/github-runner/_work/test-runners-self-hosted-postgresql-operator/test-runners-self-hosted-postgresql-operator/.tox/integration/lib/python3.10/site-packages/pluggy/_callers.py\", line 181, in _multicall\n    return outcome.get_result()\n  File \"/home/ubuntu/github-runner/_work/test-runners-self-hosted-postgresql-operator/test-runners-self-hosted-postgresql-operator/.tox/integration/lib/python3.10/site-packages/pluggy/_result.py\", line 99, in get_result\n    raise exc.with_traceback(exc.__traceback__)\n  File \"/home/ubuntu/github-runner/_work/test-runners-self-hosted-postgresql-operator/test-runners-self-hosted-postgresql-operator/.tox/integration/lib/python3.10/site-packages/pluggy/_callers.py\", line 166, in _multicall\n    teardown.throw(outcome._exception)\n  File \"/home/ubuntu/github-runner/_work/test-runners-self-hosted-postgresql-operator/test-runners-self-hosted-postgresql-operator/.tox/integration/lib/python3.10/site-packages/_pytest/threadexception.py\", line 87, in pytest_runtest_call\n    yield from thread_exception_runtest_hook()\n  File \"/home/ubuntu/github-runner/_work/test-runners-self-hosted-postgresql-operator/test-runners-self-hosted-postgresql-operator/.tox/integration/lib/python3.10/site-packages/_pytest/threadexception.py\", line 63, in thread_exception_runtest_hook\n    yield\n  File \"/home/ubuntu/github-runner/_work/test-runners-self-hosted-postgresql-operator/test-runners-self-hosted-postgresql-operator/.tox/integration/lib/python3.10/site-packages/pluggy/_callers.py\", line 166, in _multicall\n    teardown.throw(outcome._exception)\n  File \"/home/ubuntu/github-runner/_work/test-runners-self-hosted-postgresql-operator/test-runners-self-hosted-postgresql-operator/.tox/integration/lib/python3.10/site-packages/_pytest/unraisableexception.py\", line 90, in pytest_runtest_call\n    yield from unraisable_exception_runtest_hook()\n  File \"/home/ubuntu/github-runner/_work/test-runners-self-hosted-postgresql-operator/test-runners-self-hosted-postgresql-operator/.tox/integration/lib/python3.10/site-packages/_pytest/unraisableexception.py\", line 65, in unraisable_exception_runtest_hook\n    yield\n  File \"/home/ubuntu/github-runner/_work/test-runners-self-hosted-postgresql-operator/test-runners-self-hosted-postgresql-operator/.tox/integration/lib/python3.10/site-packages/pluggy/_callers.py\", line 166, in _multicall\n    teardown.throw(outcome._exception)\n  File \"/home/ubuntu/github-runner/_work/test-runners-self-hosted-postgresql-operator/test-runners-self-hosted-postgresql-operator/.tox/integration/lib/python3.10/site-packages/_pytest/logging.py\", line 849, in pytest_runtest_call\n    yield from self._runtest_for(item, \"call\")\n  File \"/home/ubuntu/github-runner/_work/test-runners-self-hosted-postgresql-operator/test-runners-self-hosted-postgresql-operator/.tox/integration/lib/python3.10/site-packages/_pytest/logging.py\", line 832, in _runtest_for\n    yield\n  File \"/home/ubuntu/github-runner/_work/test-runners-self-hosted-postgresql-operator/test-runners-self-hosted-postgresql-operator/.tox/integration/lib/python3.10/site-packages/pluggy/_callers.py\", line 166, in _multicall\n    teardown.throw(outcome._exception)\n  File \"/home/ubuntu/github-runner/_work/test-runners-self-hosted-postgresql-operator/test-runners-self-hosted-postgresql-operator/.tox/integration/lib/python3.10/site-packages/_pytest/capture.py\", line 883, in pytest_runtest_call\n    return (yield)\n  File \"/home/ubuntu/github-runner/_work/test-runners-self-hosted-postgresql-operator/test-runners-self-hosted-postgresql-operator/.tox/integration/lib/python3.10/site-packages/pluggy/_callers.py\", line 166, in _multicall\n    teardown.throw(outcome._exception)\n  File \"/home/ubuntu/github-runner/_work/test-runners-self-hosted-postgresql-operator/test-runners-self-hosted-postgresql-operator/.tox/integration/lib/python3.10/site-packages/_pytest/skipping.py\", line 256, in pytest_runtest_call\n    return (yield)\n  File \"/home/ubuntu/github-runner/_work/test-runners-self-hosted-postgresql-operator/test-runners-self-hosted-postgresql-operator/.tox/integration/lib/python3.10/site-packages/pluggy/_callers.py\", line 102, in _multicall\n    res = hook_impl.function(*args)\n  File \"/home/ubuntu/github-runner/_work/test-runners-self-hosted-postgresql-operator/test-runners-self-hosted-postgresql-operator/.tox/integration/lib/python3.10/site-packages/_pytest/runner.py\", line 182, in pytest_runtest_call\n    raise e\n  File \"/home/ubuntu/github-runner/_work/test-runners-self-hosted-postgresql-operator/test-runners-self-hosted-postgresql-operator/.tox/integration/lib/python3.10/site-packages/_pytest/runner.py\", line 172, in pytest_runtest_call\n    item.runtest()\n  File \"/home/ubuntu/github-runner/_work/test-runners-self-hosted-postgresql-operator/test-runners-self-hosted-postgresql-operator/.tox/integration/lib/python3.10/site-packages/_pytest/python.py\", line 1772, in runtest\n    self.ihook.pytest_pyfunc_call(pyfuncitem=self)\n  File \"/home/ubuntu/github-runner/_work/test-runners-self-hosted-postgresql-operator/test-runners-self-hosted-postgresql-operator/.tox/integration/lib/python3.10/site-packages/pluggy/_hooks.py\", line 501, in __call__\n    return self._hookexec(self.name, self._hookimpls.copy(), kwargs, firstresult)\n  File \"/home/ubuntu/github-runner/_work/test-runners-self-hosted-postgresql-operator/test-runners-self-hosted-postgresql-operator/.tox/integration/lib/python3.10/site-packages/pluggy/_manager.py\", line 119, in _hookexec\n    return self._inner_hookexec(hook_name, methods, kwargs, firstresult)\n  File \"/home/ubuntu/github-runner/_work/test-runners-self-hosted-postgresql-operator/test-runners-self-hosted-postgresql-operator/.tox/integration/lib/python3.10/site-packages/pluggy/_callers.py\", line 181, in _multicall\n    return outcome.get_result()\n  File \"/home/ubuntu/github-runner/_work/test-runners-self-hosted-postgresql-operator/test-runners-self-hosted-postgresql-operator/.tox/integration/lib/python3.10/site-packages/pluggy/_result.py\", line 99, in get_result\n    raise exc.with_traceback(exc.__traceback__)\n  File \"/home/ubuntu/github-runner/_work/test-runners-self-hosted-postgresql-operator/test-runners-self-hosted-postgresql-operator/.tox/integration/lib/python3.10/site-packages/pluggy/_callers.py\", line 102, in _multicall\n    res = hook_impl.function(*args)\n  File \"/home/ubuntu/github-runner/_work/test-runners-self-hosted-postgresql-operator/test-runners-self-hosted-postgresql-operator/.tox/integration/lib/python3.10/site-packages/_pytest/python.py\", line 195, in pytest_pyfunc_call\n    result = testfunction(**testargs)\n  File \"/home/ubuntu/github-runner/_work/test-runners-self-hosted-postgresql-operator/test-runners-self-hosted-postgresql-operator/.tox/integration/lib/python3.10/site-packages/pytest_asyncio/plugin.py\", line 532, in inner\n    _loop.run_until_complete(task)\n  File \"/usr/lib/python3.10/asyncio/base_events.py\", line 649, in run_until_complete\n    return future.result()\n  File \"/home/ubuntu/github-runner/_work/test-runners-self-hosted-postgresql-operator/test-runners-self-hosted-postgresql-operator/tests/integration/test_tls.py\", line 146, in test_tls_enabled\n    assert await primary_changed(ops_test, primary), \"primary not changed\"\n  File \"/home/ubuntu/github-runner/_work/test-runners-self-hosted-postgresql-operator/test-runners-self-hosted-postgresql-operator/.tox/integration/lib/python3.10/site-packages/tenacity/_asyncio.py\", line 88, in async_wrapped\n    return await fn(*args, **kwargs)\n  File \"/home/ubuntu/github-runner/_work/test-runners-self-hosted-postgresql-operator/test-runners-self-hosted-postgresql-operator/.tox/integration/lib/python3.10/site-packages/tenacity/_asyncio.py\", line 47, in __call__\n    do = self.iter(retry_state=retry_state)\n  File \"/home/ubuntu/github-runner/_work/test-runners-self-hosted-postgresql-operator/test-runners-self-hosted-postgresql-operator/.tox/integration/lib/python3.10/site-packages/tenacity/__init__.py\", line 326, in iter\n    raise retry_exc from fut.exception()\ntenacity.RetryError: RetryError[<Future at 0x76fc96e4fe80 state=finished returned bool>]","flaky":false,"newFailed":false,"newBroken":false,"newPassed":false,"retriesCount":0,"retriesStatusChange":false,"beforeStages":[{"name":"event_loop","time":{"start":1712971373285,"stop":1712971373285,"duration":0},"status":"passed","steps":[],"attachments":[],"parameters":[],"stepsCount":0,"shouldDisplayMessage":false,"attachmentsCount":0,"hasContent":false,"attachmentStep":false},{"name":"ops_test","time":{"start":1712971373286,"stop":1712971373755,"duration":469},"status":"passed","steps":[],"attachments":[],"parameters":[],"stepsCount":0,"shouldDisplayMessage":false,"attachmentsCount":0,"hasContent":false,"attachmentStep":false},{"name":"tmp_path_factory","time":{"start":1712971373286,"stop":1712971373286,"duration":0},"status":"passed","steps":[],"attachments":[],"parameters":[],"stepsCount":0,"shouldDisplayMessage":false,"attachmentsCount":0,"hasContent":false,"attachmentStep":false},{"name":"abort_on_fail","time":{"start":1712971395964,"stop":1712971395964,"duration":0},"status":"passed","steps":[],"attachments":[],"parameters":[],"stepsCount":0,"shouldDisplayMessage":false,"attachmentsCount":0,"hasContent":false,"attachmentStep":false}],"testStage":{"description":"Test that TLS is enabled when relating to the TLS Certificates Operator.","status":"broken","statusMessage":"tenacity.RetryError: RetryError[<Future at 0x76fc96e4fe80 state=finished returned bool>]","statusTrace":"Traceback (most recent call last):\n  File \"/home/ubuntu/github-runner/_work/test-runners-self-hosted-postgresql-operator/test-runners-self-hosted-postgresql-operator/.tox/integration/lib/python3.10/site-packages/_pytest/runner.py\", line 340, in from_call\n    result: Optional[TResult] = func()\n  File \"/home/ubuntu/github-runner/_work/test-runners-self-hosted-postgresql-operator/test-runners-self-hosted-postgresql-operator/.tox/integration/lib/python3.10/site-packages/_pytest/runner.py\", line 240, in <lambda>\n    lambda: runtest_hook(item=item, **kwds), when=when, reraise=reraise\n  File \"/home/ubuntu/github-runner/_work/test-runners-self-hosted-postgresql-operator/test-runners-self-hosted-postgresql-operator/.tox/integration/lib/python3.10/site-packages/pluggy/_hooks.py\", line 501, in __call__\n    return self._hookexec(self.name, self._hookimpls.copy(), kwargs, firstresult)\n  File \"/home/ubuntu/github-runner/_work/test-runners-self-hosted-postgresql-operator/test-runners-self-hosted-postgresql-operator/.tox/integration/lib/python3.10/site-packages/pluggy/_manager.py\", line 119, in _hookexec\n    return self._inner_hookexec(hook_name, methods, kwargs, firstresult)\n  File \"/home/ubuntu/github-runner/_work/test-runners-self-hosted-postgresql-operator/test-runners-self-hosted-postgresql-operator/.tox/integration/lib/python3.10/site-packages/pluggy/_callers.py\", line 181, in _multicall\n    return outcome.get_result()\n  File \"/home/ubuntu/github-runner/_work/test-runners-self-hosted-postgresql-operator/test-runners-self-hosted-postgresql-operator/.tox/integration/lib/python3.10/site-packages/pluggy/_result.py\", line 99, in get_result\n    raise exc.with_traceback(exc.__traceback__)\n  File \"/home/ubuntu/github-runner/_work/test-runners-self-hosted-postgresql-operator/test-runners-self-hosted-postgresql-operator/.tox/integration/lib/python3.10/site-packages/pluggy/_callers.py\", line 166, in _multicall\n    teardown.throw(outcome._exception)\n  File \"/home/ubuntu/github-runner/_work/test-runners-self-hosted-postgresql-operator/test-runners-self-hosted-postgresql-operator/.tox/integration/lib/python3.10/site-packages/_pytest/threadexception.py\", line 87, in pytest_runtest_call\n    yield from thread_exception_runtest_hook()\n  File \"/home/ubuntu/github-runner/_work/test-runners-self-hosted-postgresql-operator/test-runners-self-hosted-postgresql-operator/.tox/integration/lib/python3.10/site-packages/_pytest/threadexception.py\", line 63, in thread_exception_runtest_hook\n    yield\n  File \"/home/ubuntu/github-runner/_work/test-runners-self-hosted-postgresql-operator/test-runners-self-hosted-postgresql-operator/.tox/integration/lib/python3.10/site-packages/pluggy/_callers.py\", line 166, in _multicall\n    teardown.throw(outcome._exception)\n  File \"/home/ubuntu/github-runner/_work/test-runners-self-hosted-postgresql-operator/test-runners-self-hosted-postgresql-operator/.tox/integration/lib/python3.10/site-packages/_pytest/unraisableexception.py\", line 90, in pytest_runtest_call\n    yield from unraisable_exception_runtest_hook()\n  File \"/home/ubuntu/github-runner/_work/test-runners-self-hosted-postgresql-operator/test-runners-self-hosted-postgresql-operator/.tox/integration/lib/python3.10/site-packages/_pytest/unraisableexception.py\", line 65, in unraisable_exception_runtest_hook\n    yield\n  File \"/home/ubuntu/github-runner/_work/test-runners-self-hosted-postgresql-operator/test-runners-self-hosted-postgresql-operator/.tox/integration/lib/python3.10/site-packages/pluggy/_callers.py\", line 166, in _multicall\n    teardown.throw(outcome._exception)\n  File \"/home/ubuntu/github-runner/_work/test-runners-self-hosted-postgresql-operator/test-runners-self-hosted-postgresql-operator/.tox/integration/lib/python3.10/site-packages/_pytest/logging.py\", line 849, in pytest_runtest_call\n    yield from self._runtest_for(item, \"call\")\n  File \"/home/ubuntu/github-runner/_work/test-runners-self-hosted-postgresql-operator/test-runners-self-hosted-postgresql-operator/.tox/integration/lib/python3.10/site-packages/_pytest/logging.py\", line 832, in _runtest_for\n    yield\n  File \"/home/ubuntu/github-runner/_work/test-runners-self-hosted-postgresql-operator/test-runners-self-hosted-postgresql-operator/.tox/integration/lib/python3.10/site-packages/pluggy/_callers.py\", line 166, in _multicall\n    teardown.throw(outcome._exception)\n  File \"/home/ubuntu/github-runner/_work/test-runners-self-hosted-postgresql-operator/test-runners-self-hosted-postgresql-operator/.tox/integration/lib/python3.10/site-packages/_pytest/capture.py\", line 883, in pytest_runtest_call\n    return (yield)\n  File \"/home/ubuntu/github-runner/_work/test-runners-self-hosted-postgresql-operator/test-runners-self-hosted-postgresql-operator/.tox/integration/lib/python3.10/site-packages/pluggy/_callers.py\", line 166, in _multicall\n    teardown.throw(outcome._exception)\n  File \"/home/ubuntu/github-runner/_work/test-runners-self-hosted-postgresql-operator/test-runners-self-hosted-postgresql-operator/.tox/integration/lib/python3.10/site-packages/_pytest/skipping.py\", line 256, in pytest_runtest_call\n    return (yield)\n  File \"/home/ubuntu/github-runner/_work/test-runners-self-hosted-postgresql-operator/test-runners-self-hosted-postgresql-operator/.tox/integration/lib/python3.10/site-packages/pluggy/_callers.py\", line 102, in _multicall\n    res = hook_impl.function(*args)\n  File \"/home/ubuntu/github-runner/_work/test-runners-self-hosted-postgresql-operator/test-runners-self-hosted-postgresql-operator/.tox/integration/lib/python3.10/site-packages/_pytest/runner.py\", line 182, in pytest_runtest_call\n    raise e\n  File \"/home/ubuntu/github-runner/_work/test-runners-self-hosted-postgresql-operator/test-runners-self-hosted-postgresql-operator/.tox/integration/lib/python3.10/site-packages/_pytest/runner.py\", line 172, in pytest_runtest_call\n    item.runtest()\n  File \"/home/ubuntu/github-runner/_work/test-runners-self-hosted-postgresql-operator/test-runners-self-hosted-postgresql-operator/.tox/integration/lib/python3.10/site-packages/_pytest/python.py\", line 1772, in runtest\n    self.ihook.pytest_pyfunc_call(pyfuncitem=self)\n  File \"/home/ubuntu/github-runner/_work/test-runners-self-hosted-postgresql-operator/test-runners-self-hosted-postgresql-operator/.tox/integration/lib/python3.10/site-packages/pluggy/_hooks.py\", line 501, in __call__\n    return self._hookexec(self.name, self._hookimpls.copy(), kwargs, firstresult)\n  File \"/home/ubuntu/github-runner/_work/test-runners-self-hosted-postgresql-operator/test-runners-self-hosted-postgresql-operator/.tox/integration/lib/python3.10/site-packages/pluggy/_manager.py\", line 119, in _hookexec\n    return self._inner_hookexec(hook_name, methods, kwargs, firstresult)\n  File \"/home/ubuntu/github-runner/_work/test-runners-self-hosted-postgresql-operator/test-runners-self-hosted-postgresql-operator/.tox/integration/lib/python3.10/site-packages/pluggy/_callers.py\", line 181, in _multicall\n    return outcome.get_result()\n  File \"/home/ubuntu/github-runner/_work/test-runners-self-hosted-postgresql-operator/test-runners-self-hosted-postgresql-operator/.tox/integration/lib/python3.10/site-packages/pluggy/_result.py\", line 99, in get_result\n    raise exc.with_traceback(exc.__traceback__)\n  File \"/home/ubuntu/github-runner/_work/test-runners-self-hosted-postgresql-operator/test-runners-self-hosted-postgresql-operator/.tox/integration/lib/python3.10/site-packages/pluggy/_callers.py\", line 102, in _multicall\n    res = hook_impl.function(*args)\n  File \"/home/ubuntu/github-runner/_work/test-runners-self-hosted-postgresql-operator/test-runners-self-hosted-postgresql-operator/.tox/integration/lib/python3.10/site-packages/_pytest/python.py\", line 195, in pytest_pyfunc_call\n    result = testfunction(**testargs)\n  File \"/home/ubuntu/github-runner/_work/test-runners-self-hosted-postgresql-operator/test-runners-self-hosted-postgresql-operator/.tox/integration/lib/python3.10/site-packages/pytest_asyncio/plugin.py\", line 532, in inner\n    _loop.run_until_complete(task)\n  File \"/usr/lib/python3.10/asyncio/base_events.py\", line 649, in run_until_complete\n    return future.result()\n  File \"/home/ubuntu/github-runner/_work/test-runners-self-hosted-postgresql-operator/test-runners-self-hosted-postgresql-operator/tests/integration/test_tls.py\", line 146, in test_tls_enabled\n    assert await primary_changed(ops_test, primary), \"primary not changed\"\n  File \"/home/ubuntu/github-runner/_work/test-runners-self-hosted-postgresql-operator/test-runners-self-hosted-postgresql-operator/.tox/integration/lib/python3.10/site-packages/tenacity/_asyncio.py\", line 88, in async_wrapped\n    return await fn(*args, **kwargs)\n  File \"/home/ubuntu/github-runner/_work/test-runners-self-hosted-postgresql-operator/test-runners-self-hosted-postgresql-operator/.tox/integration/lib/python3.10/site-packages/tenacity/_asyncio.py\", line 47, in __call__\n    do = self.iter(retry_state=retry_state)\n  File \"/home/ubuntu/github-runner/_work/test-runners-self-hosted-postgresql-operator/test-runners-self-hosted-postgresql-operator/.tox/integration/lib/python3.10/site-packages/tenacity/__init__.py\", line 326, in iter\n    raise retry_exc from fut.exception()\ntenacity.RetryError: RetryError[<Future at 0x76fc96e4fe80 state=finished returned bool>]","steps":[],"attachments":[{"uid":"3b58df48e20c6eb0","name":"log","source":"3b58df48e20c6eb0.txt","type":"text/plain","size":9000}],"parameters":[],"stepsCount":0,"shouldDisplayMessage":true,"attachmentsCount":1,"hasContent":true,"attachmentStep":false},"afterStages":[{"name":"abort_on_fail::0","time":{"start":1712972652096,"stop":1712972652097,"duration":1},"status":"passed","steps":[],"attachments":[],"parameters":[],"stepsCount":0,"shouldDisplayMessage":false,"attachmentsCount":0,"hasContent":false,"attachmentStep":false},{"name":"ops_test::finalizer","time":{"start":1712972652109,"stop":1712972652711,"duration":602},"status":"passed","steps":[],"attachments":[],"parameters":[],"stepsCount":0,"shouldDisplayMessage":false,"attachmentsCount":0,"hasContent":false,"attachmentStep":false},{"name":"event_loop::2","time":{"start":1712972652712,"stop":1712972652713,"duration":1},"status":"passed","steps":[],"attachments":[],"parameters":[],"stepsCount":0,"shouldDisplayMessage":false,"attachmentsCount":0,"hasContent":false,"attachmentStep":false},{"name":"event_loop::_close_event_loop","time":{"start":1712972652713,"stop":1712972652713,"duration":0},"status":"passed","steps":[],"attachments":[],"parameters":[],"stepsCount":0,"shouldDisplayMessage":false,"attachmentsCount":0,"hasContent":false,"attachmentStep":false},{"name":"event_loop::_provide_clean_event_loop","time":{"start":1712972652713,"stop":1712972652715,"duration":2},"status":"passed","steps":[],"attachments":[],"parameters":[],"stepsCount":0,"shouldDisplayMessage":false,"attachmentsCount":0,"hasContent":false,"attachmentStep":false}],"labels":[{"name":"tag","value":"group(1)"},{"name":"tag","value":"asyncio"},{"name":"parentSuite","value":"tests.integration"},{"name":"suite","value":"test_tls"},{"name":"host","value":"large-522-f4795e7c3a61912e909502a6"},{"name":"thread","value":"10007-MainThread"},{"name":"framework","value":"pytest"},{"name":"language","value":"cpython3"},{"name":"package","value":"tests.integration.test_tls"},{"name":"resultFormat","value":"allure2"}],"parameters":[],"links":[],"hidden":false,"retry":false,"extra":{"severity":"normal","retries":[],"categories":[{"name":"Test defects","matchedStatuses":[],"flaky":false}],"history":{"statistic":{"failed":0,"broken":2,"skipped":0,"passed":0,"unknown":0,"total":2},"items":[{"uid":"b938398e87f7d210","reportUrl":"../2//#testresult/b938398e87f7d210","status":"broken","statusDetails":"Exception: ('Expected command %s to succeed instead it failed: %s', \"grep 'connection authorized: user=rewind database=postgres SSL enabled' /var/snap/charmed-postgresql/common/var/log/postgresql/postgresql-*.log\", 2)","time":{"start":1712885281687,"stop":1712886164714,"duration":883027}}]},"tags":["asyncio","group(1)"]},"source":"53e62bd92de0cd9a.json","parameterValues":[]}